Workbook

Sheet Sheet1
A1: [ 인천소방학교(221210) ]
A2: 품 명 | B2: 규 격 | C2: 단위 | D2: 수량 | E2: 재 료 비 | G2: 노 무 비 | I2: 경 비 | K2: 합 계 | M2: 비 고 | N2: 품목코드 | O2: 변수 | P2: 설정 | Q2: 공종코드 | R2: 일위 | S2: 단산 | T2: 자재 | U2: 손료적용 | V2: 손료저장 | W2: 적용율 | X2: JUK1 | Y2: JUK2 | Z2: JUK3 | AA2: JUK4 | AB2: JUK5 | AC2: JUK6 | AD2: JUK7 | AE2: JUK8 | AF2: JUK9 | AG2: JUK10 | AH2: JUK11 | AI2: JUK12 | AJ2: JUK13 | AK2: JUK14 | AL2: JUK15 | AM2: JUK16 | AN2: JUK17 | AO2: JUK18 | AP2: JUK19 | AQ2: JUK20 | AR2: 자재구분 | AS2: 공종구분 | AT2: 공종레벨 | AU2: 공종+자재 | AV2: 고유번호
E3: 단 가 | F3: 금 액 | G3: 단 가 | H3: 금 액 | I3: 단 가 | J3: 금 액 | K3: 단 가 | L3: 금 액
A4: 010101 공통 가설 공사 | B4: 01.본관동 및 생활관, 후생관 | Q4: 010101
A5: 가설울타리설치및 해체 | B5: EGI휀스,지주높이 3.5m이하 | C5: m | D5: 990 | E5: =TRUNC([1]단가대비표!O196,0) -> 0 | F5: =TRUNC(E5*D5, 0) -> 0 | G5: =TRUNC([1]단가대비표!P196,0) -> 0 | H5: =TRUNC(G5*D5, 0) -> 0 | I5: =TRUNC([1]단가대비표!V196,0) -> 22749 | J5: =TRUNC(I5*D5, 0) -> 22521510 | K5: =TRUNC(E5+G5+I5, 0) -> 22749 | L5: =TRUNC(F5+H5+J5, 0) -> 22521510 | M5: 노무비율 0% | N5: 4477177097F115B34CE24775BBCC4 | Q5: 010101 | R5: F | S5: F | T5: T | AU5: 0101014477177097F115B34CE24775BBCC4 | AV5: 2929
A6: 조립식가설사무소/감리, 감독자 | B6: 25개월, 렌탈 | C6: M2 | D6: 180 | E6: =TRUNC([1]일위대가목록!E4,0) -> 0 | F6: =TRUNC(E6*D6, 0) -> 0 | G6: =TRUNC([1]일위대가목록!F4,0) -> 0 | H6: =TRUNC(G6*D6, 0) -> 0 | I6: =TRUNC([1]일위대가목록!G4,0) -> 124888 | J6: =TRUNC(I6*D6, 0) -> 22479840 | K6: =TRUNC(E6+G6+I6, 0) -> 124888 | L6: =TRUNC(F6+H6+J6, 0) -> 22479840 | M6: 호표 1 | N6: 44771770A05C1591F337CE26D8B0E | Q6: 010101 | R6: T | S6: F | T6: F | AU6: 01010144771770A05C1591F337CE26D8B0E | AV6: 2915
A7: 컨테이너가설창고 | B7: 25개월, 렌탈, 3.0*6.0m | C7: 동 | D7: 2 | E7: =TRUNC([1]일위대가목록!E5,0) -> 0 | F7: =TRUNC(E7*D7, 0) -> 0 | G7: =TRUNC([1]일위대가목록!F5,0) -> 0 | H7: =TRUNC(G7*D7, 0) -> 0 | I7: =TRUNC([1]일위대가목록!G5,0) -> 1353144 | J7: =TRUNC(I7*D7, 0) -> 2706288 | K7: =TRUNC(E7+G7+I7, 0) -> 1353144 | L7: =TRUNC(F7+H7+J7, 0) -> 2706288 | M7: 호표 2 | N7: 44771770A06E15D56C0BA62B9A1F9 | Q7: 010101 | R7: T | S7: F | T7: F | AU7: 01010144771770A06E15D56C0BA62B9A1F9 | AV7: 2846
A8: 컨테이너가설실험실 | B8: 25개월, 렌탈, 3.0*6.0m | C8: 동 | D8: 3 | E8: =TRUNC([1]일위대가목록!E6,0) -> 0 | F8: =TRUNC(E8*D8, 0) -> 0 | G8: =TRUNC([1]일위대가목록!F6,0) -> 0 | H8: =TRUNC(G8*D8, 0) -> 0 | I8: =TRUNC([1]일위대가목록!G6,0) -> 1228144 | J8: =TRUNC(I8*D8, 0) -> 3684432 | K8: =TRUNC(E8+G8+I8, 0) -> 1228144 | L8: =TRUNC(F8+H8+J8, 0) -> 3684432 | M8: 호표 3 | N8: 44771770A06E15D56C0BA6CBCEE91 | Q8: 010101 | R8: T | S8: F | T8: F | AU8: 01010144771770A06E15D56C0BA6CBCEE91 | AV8: 2847
A9: 폐기물보관소 | B9: 25개월, 렌탈 | C9: M2 | D9: 27 | E9: =TRUNC([1]일위대가목록!E7,0) -> 0 | F9: =TRUNC(E9*D9, 0) -> 0 | G9: =TRUNC([1]일위대가목록!F7,0) -> 0 | H9: =TRUNC(G9*D9, 0) -> 0 | I9: =TRUNC([1]일위대가목록!G7,0) -> 101893 | J9: =TRUNC(I9*D9, 0) -> 2751111 | K9: =TRUNC(E9+G9+I9, 0) -> 101893 | L9: =TRUNC(F9+H9+J9, 0) -> 2751111 | M9: 호표 4 | N9: 44771770A05C15A251EC38A14CCB8 | Q9: 010101 | R9: T | S9: F | T9: F | AU9: 01010144771770A05C15A251EC38A14CCB8 | AV9: 2843
A10: 가설게이트 | B10: 홀딩도어 L=12m, H=8m | C10: EA | D10: 1 | E10: =TRUNC([1]일위대가목록!E8,0) -> 0 | F10: =TRUNC(E10*D10, 0) -> 0 | G10: =TRUNC([1]일위대가목록!F8,0) -> 0 | H10: =TRUNC(G10*D10, 0) -> 0 | I10: =TRUNC([1]일위대가목록!G8,0) -> 1679950 | J10: =TRUNC(I10*D10, 0) -> 1679950 | K10: =TRUNC(E10+G10+I10, 0) -> 1679950 | L10: =TRUNC(F10+H10+J10, 0) -> 1679950 | M10: 호표 5 | N10: 4477177097C4150280AAAF6F57072 | Q10: 010101 | R10: T | S10: F | T10: F | AU10: 0101014477177097C4150280AAAF6F57072 | AV10: 2885
A11: 이동식 타워크레인손료 - 월 | B11: 54m*50ton | C11: MTH | D11: 12 | E11: =TRUNC([1]일위대가목록!E9,0) -> 0 | F11: =TRUNC(E11*D11, 0) -> 0 | G11: =TRUNC([1]일위대가목록!F9,0) -> 0 | H11: =TRUNC(G11*D11, 0) -> 0 | I11: =TRUNC([1]일위대가목록!G9,0) -> 19978200 | J11: =TRUNC(I11*D11, 0) -> 239738400 | K11: =TRUNC(E11+G11+I11, 0) -> 19978200 | L11: =TRUNC(F11+H11+J11, 0) -> 239738400 | M11: 호표 6 | N11: 44771770B29115CAEE25590F4A86C | Q11: 010101 | R11: T | S11: F | T11: F | AU11: 01010144771770B29115CAEE25590F4A86C | AV11: 2914
A12: 가설전기인입비 | C12: 식 | D12: 1 | E12: =TRUNC([1]일위대가목록!E10,0) -> 0 | F12: =TRUNC(E12*D12, 0) -> 0 | G12: =TRUNC([1]일위대가목록!F10,0) -> 0 | H12: =TRUNC(G12*D12, 0) -> 0 | I12: =TRUNC([1]일위대가목록!G10,0) -> 64549823 | J12: =TRUNC(I12*D12, 0) -> 64549823 | K12: =TRUNC(E12+G12+I12, 0) -> 64549823 | L12: =TRUNC(F12+H12+J12, 0) -> 64549823 | M12: 호표 7 | N12: 44771770B2A2152FBF6FD3B83D821 | Q12: 010101 | R12: T | S12: F | T12: F | AU12: 01010144771770B2A2152FBF6FD3B83D821 | AV12: 2832
A13: 가설용수비 | C13: 식 | D13: 1 | E13: =TRUNC([1]일위대가목록!E11,0) -> 0 | F13: =TRUNC(E13*D13, 0) -> 0 | G13: =TRUNC([1]일위대가목록!F11,0) -> 0 | H13: =TRUNC(G13*D13, 0) -> 0 | I13: =TRUNC([1]일위대가목록!G11,0) -> 14196871 | J13: =TRUNC(I13*D13, 0) -> 14196871 | K13: =TRUNC(E13+G13+I13, 0) -> 14196871 | L13: =TRUNC(F13+H13+J13, 0) -> 14196871 | M13: 호표 8 | N13: 4477177097F115B34C5C6434FCD32 | Q13: 010101 | R13: T | S13: F | T13: F | AU13: 0101014477177097F115B34C5C6434FCD32 | AV13: 2833
A14: 가설전력사용료 | C14: 식 | D14: 1 | E14: =TRUNC([1]일위대가목록!E12,0) -> 0 | F14: =TRUNC(E14*D14, 0) -> 0 | G14: =TRUNC([1]일위대가목록!F12,0) -> 0 | H14: =TRUNC(G14*D14, 0) -> 0 | I14: =TRUNC([1]일위대가목록!G12,0) -> 38170000 | J14: =TRUNC(I14*D14, 0) -> 38170000 | K14: =TRUNC(E14+G14+I14, 0) -> 38170000 | L14: =TRUNC(F14+H14+J14, 0) -> 38170000 | M14: 호표 9 | N14: 4477177097F115B34C5C6434FCD31 | Q14: 010101 | R14: T | S14: F | T14: F | AU14: 0101014477177097F115B34C5C6434FCD31 | AV14: 2834
A15: 건설폐기물상차비 - 중간처리 | B15: 16톤압롤트럭(20m3) | C15: TON | D15: 363.351 | E15: =TRUNC([1]단가대비표!O205,0) -> 0 | F15: =TRUNC(E15*D15, 0) -> 0 | G15: =TRUNC([1]단가대비표!P205,0) -> 0 | H15: =TRUNC(G15*D15, 0) -> 0 | I15: =TRUNC([1]단가대비표!V205,0) -> 3168 | J15: =TRUNC(I15*D15, 0) -> 1151095 | K15: =TRUNC(E15+G15+I15, 0) -> 3168 | L15: =TRUNC(F15+H15+J15, 0) -> 1151095 | N15: 44771770C33C1564727CCF91C5A2A | Q15: 010101 | R15: F | S15: F | T15: T | AU15: 01010144771770C33C1564727CCF91C5A2A | AV15: 2836
E16: =TRUNC([1]단가대비표!O780,0) -> 0 | F16: =TRUNC(E16*D16, 0) -> 0 | G16: =TRUNC([1]단가대비표!P780,0) -> 0 | H16: =TRUNC(G16*D16, 0) -> 0 | I16: =TRUNC([1]단가대비표!V780,0) -> 0 | J16: =TRUNC(I16*D16, 0) -> 0 | K16: =TRUNC(E16+G16+I16, 0) -> 0 | L16: =TRUNC(F16+H16+J16, 0) -> 0 | N16: 45C61727F3E315DA92B49D6357B297CF6556C | Q16: 010101 | R16: F | S16: F | T16: T | AU16: 01010145C61727F3E315DA92B49D6357B297CF6556C | AV16: 2837
A17: [임시소방시설] | E17: =TRUNC([1]단가대비표!O795,0) -> 0 | F17: =TRUNC(E17*D17, 0) -> 0 | G17: =TRUNC([1]단가대비표!P795,0) -> 0 | H17: =TRUNC(G17*D17, 0) -> 0 | I17: =TRUNC([1]단가대비표!V795,0) -> 0 | J17: =TRUNC(I17*D17, 0) -> 0 | K17: =TRUNC(E17+G17+I17, 0) -> 0 | L17: =TRUNC(F17+H17+J17, 0) -> 0 | N17: 45C61727F3E315DA92B49D6357B297CF65440 | Q17: 010101 | R17: F | S17: F | T17: T | AU17: 01010145C61727F3E315DA92B49D6357B297CF65440 | AV17: 2930
A18: 휴대용확성기 | C18: EA | D18: 1 | E18: =TRUNC([1]단가대비표!O796,0) -> 50000 | F18: =TRUNC(E18*D18, 0) -> 50000 | G18: =TRUNC([1]단가대비표!P796,0) -> 0 | H18: =TRUNC(G18*D18, 0) -> 0 | I18: =TRUNC([1]단가대비표!V796,0) -> 0 | J18: =TRUNC(I18*D18, 0) -> 0 | K18: =TRUNC(E18+G18+I18, 0) -> 50000 | L18: =TRUNC(F18+H18+J18, 0) -> 50000 | M18: 견적 | N18: 45C61727F3E315DA92B49D6357B297CF65441 | Q18: 010101 | R18: F | S18: F | T18: T | AU18: 01010145C61727F3E315DA92B49D6357B297CF65441 | AV18: 2931
A19: 간이피난유도선 | B19: 100M용 | C19: SET | D19: 5 | E19: =TRUNC([1]단가대비표!O797,0) -> 803756 | F19: =TRUNC(E19*D19, 0) -> 4018780 | G19: =TRUNC([1]단가대비표!P797,0) -> 0 | H19: =TRUNC(G19*D19, 0) -> 0 | I19: =TRUNC([1]단가대비표!V797,0) -> 0 | J19: =TRUNC(I19*D19, 0) -> 0 | K19: =TRUNC(E19+G19+I19, 0) -> 803756 | L19: =TRUNC(F19+H19+J19, 0) -> 4018780 | M19: 견적 | N19: 45C61727F3E315DA92B49D6357B297CF653A1 | Q19: 010101 | R19: F | S19: F | T19: T | AU19: 01010145C61727F3E315DA92B49D6357B297CF653A1 | AV19: 2932
A20: 소화기 | B20: 대형분말소화기 | C20: 개 | D20: 11 | E20: =TRUNC([1]단가대비표!O798,0) -> 160000 | F20: =TRUNC(E20*D20, 0) -> 1760000 | G20: =TRUNC([1]단가대비표!P798,0) -> 0 | H20: =TRUNC(G20*D20, 0) -> 0 | I20: =TRUNC([1]단가대비표!V798,0) -> 0 | J20: =TRUNC(I20*D20, 0) -> 0 | K20: =TRUNC(E20+G20+I20, 0) -> 160000 | L20: =TRUNC(F20+H20+J20, 0) -> 1760000 | M20: 견적 | N20: 45C61727F3E315DA92B49D6357B297CF653A0 | Q20: 010101 | R20: F | S20: F | T20: T | AU20: 01010145C61727F3E315DA92B49D6357B297CF653A0 | AV20: 2933
A24: [ 합 계 ] | F24: =SUM(F5:F23) -> 5828780 | H24: =SUM(H5:H23) -> 0 | J24: =SUM(J5:J23) -> 413629320 | L24: =SUM(L5:L23) -> 419458100 | N24: TOTAL
A25: 010102 가 설 공 사 | B25: 01.본관동 및 생활관, 후생관 | Q25: 010102
A26: 조립말비계 (강관) | B26: 3개월 이하 1단,2m | C26: 대 | D26: 62 | E26: =TRUNC([1]단가대비표!O200,0) -> 23445 | F26: =TRUNC(E26*D26, 0) -> 1453590 | G26: =TRUNC([1]단가대비표!P200,0) -> 74241 | H26: =TRUNC(G26*D26, 0) -> 4602942 | I26: =TRUNC([1]단가대비표!V200,0) -> 0 | J26: =TRUNC(I26*D26, 0) -> 0 | K26: =TRUNC(E26+G26+I26, 0) -> 97686 | L26: =TRUNC(F26+H26+J26, 0) -> 6056532 | M26: 노무비 75.9% | N26: 4477177097D615E61A0915A2BF7CF | Q26: 010102 | R26: F | S26: F | T26: T | AU26: 0101024477177097D615E61A0915A2BF7CF | AV26: 2961
A27: 시스템비계 | B27: 10m이하 | C27: ㎡ | D27: 10679 | E27: =TRUNC([1]단가대비표!O197,0) -> 372 | F27: =TRUNC(E27*D27, 0) -> 3972588 | G27: =TRUNC([1]단가대비표!P197,0) -> 12003 | H27: =TRUNC(G27*D27, 0) -> 128180037 | I27: =TRUNC([1]단가대비표!V197,0) -> 0 | J27: =TRUNC(I27*D27, 0) -> 0 | K27: =TRUNC(E27+G27+I27, 0) -> 12375 | L27: =TRUNC(F27+H27+J27, 0) -> 132152625 | M27: 노무비 96.9% | N27: 4477177097D615E61A472B48FEC09 | Q27: 010102 | R27: F | S27: F | T27: T | AU27: 0101024477177097D615E61A472B48FEC09 | AV27: 2962
A28: 강관동바리(0.6m초과) | B28: 3.5m이하, 3개월이하 | C28: ㎡ | D28: 58 | E28: =TRUNC([1]단가대비표!O201,0) -> 2637 | F28: =TRUNC(E28*D28, 0) -> 152946 | G28: =TRUNC([1]단가대비표!P201,0) -> 8828 | H28: =TRUNC(G28*D28, 0) -> 512024 | I28: =TRUNC([1]단가대비표!V201,0) -> 0 | J28: =TRUNC(I28*D28, 0) -> 0 | K28: =TRUNC(E28+G28+I28, 0) -> 11465 | L28: =TRUNC(F28+H28+J28, 0) -> 664970 | M28: 노무비 76.9% | N28: 4477177097D615D58854549FB67D6 | Q28: 010102 | R28: F | S28: F | T28: T | AU28: 0101024477177097D615D58854549FB67D6 | AV28: 2963
A29: 강관동바리(0.6m초과) | B29: 3.5-4.2m이하, 3개월이하 | C29: ㎡ | D29: 3505 | E29: =TRUNC([1]단가대비표!O202,0) -> 2665 | F29: =TRUNC(E29*D29, 0) -> 9340825 | G29: =TRUNC([1]단가대비표!P202,0) -> 10657 | H29: =TRUNC(G29*D29, 0) -> 37352785 | I29: =TRUNC([1]단가대비표!V202,0) -> 0 | J29: =TRUNC(I29*D29, 0) -> 0 | K29: =TRUNC(E29+G29+I29, 0) -> 13322 | L29: =TRUNC(F29+H29+J29, 0) -> 46693610 | M29: 노무비 79.9% | N29: 4477177097D615D58854548D0E224 | Q29: 010102 | R29: F | S29: F | T29: T | AU29: 0101024477177097D615D58854548D0E224 | AV29: 2964
A30: 시스템동바리 설치 및 해체 | B30: 10m 이하 | C30: 10공M3 | D30: 1036 | E30: =TRUNC([1]일위대가목록!E13,0) -> 6050 | F30: =TRUNC(E30*D30, 0) -> 6267800 | G30: =TRUNC([1]일위대가목록!F13,0) -> 175810 | H30: =TRUNC(G30*D30, 0) -> 182139160 | I30: =TRUNC([1]일위대가목록!G13,0) -> 7130 | J30: =TRUNC(I30*D30, 0) -> 7386680 | K30: =TRUNC(E30+G30+I30, 0) -> 188990 | L30: =TRUNC(F30+H30+J30, 0) -> 195793640 | M30: 호표 10 | N30: 4477177097D615D59AB4675ABFE73 | Q30: 010102 | R30: T | S30: F | T30: F | AU30: 0101024477177097D615D59AB4675ABFE73 | AV30: 2562
A31: 현장 정리 | B31: RC조 | C31: ㎡ | D31: 12235 | E31: =TRUNC([1]단가대비표!O206,0) -> 129 | F31: =TRUNC(E31*D31, 0) -> 1578315 | G31: =TRUNC([1]단가대비표!P206,0) -> 12741 | H31: =TRUNC(G31*D31, 0) -> 155886135 | I31: =TRUNC([1]단가대비표!V206,0) -> 0 | J31: =TRUNC(I31*D31, 0) -> 0 | K31: =TRUNC(E31+G31+I31, 0) -> 12870 | L31: =TRUNC(F31+H31+J31, 0) -> 157464450 | M31: 노무비 98.9% | N31: 44771770C33C155BF49FA7D6EE412 | Q31: 010102 | R31: F | S31: F | T31: T | AU31: 01010244771770C33C155BF49FA7D6EE412 | AV31: 2965
A32: 구조부 먹매김 | B32: 일반 | C32: M2 | D32: 12235 | E32: =TRUNC([1]일위대가목록!E14,0) -> 0 | F32: =TRUNC(E32*D32, 0) -> 0 | G32: =TRUNC([1]일위대가목록!F14,0) -> 897 | H32: =TRUNC(G32*D32, 0) -> 10974795 | I32: =TRUNC([1]일위대가목록!G14,0) -> 0 | J32: =TRUNC(I32*D32, 0) -> 0 | K32: =TRUNC(E32+G32+I32, 0) -> 897 | L32: =TRUNC(F32+H32+J32, 0) -> 10974795 | M32: 호표 11 | N32: 44771770C30015F0D8B80E316CC6B | Q32: 010102 | R32: T | S32: F | T32: F | AU32: 01010244771770C30015F0D8B80E316CC6B | AV32: 2565
A33: 거푸집 먹매김 | B33: 일반 | C33: M2 | D33: 12235 | E33: =TRUNC([1]일위대가목록!E15,0) -> 0 | F33: =TRUNC(E33*D33, 0) -> 0 | G33: =TRUNC([1]일위대가목록!F15,0) -> 2093 | H33: =TRUNC(G33*D33, 0) -> 25607855 | I33: =TRUNC([1]일위대가목록!G15,0) -> 0 | J33: =TRUNC(I33*D33, 0) -> 0 | K33: =TRUNC(E33+G33+I33, 0) -> 2093 | L33: =TRUNC(F33+H33+J33, 0) -> 25607855 | M33: 호표 12 | N33: 44771770C30015F0D8B8291F12DAA | Q33: 010102 | R33: T | S33: F | T33: F | AU33: 01010244771770C30015F0D8B8291F12DAA | AV33: 2566
A34: 건축물보양 - 콘크리트 | B34: 살수 | C34: M2 | D34: 16291 | E34: =TRUNC([1]일위대가목록!E16,0) -> 0 | F34: =TRUNC(E34*D34, 0) -> 0 | G34: =TRUNC([1]일위대가목록!F16,0) -> 512 | H34: =TRUNC(G34*D34, 0) -> 8340992 | I34: =TRUNC([1]일위대가목록!G16,0) -> 0 | J34: =TRUNC(I34*D34, 0) -> 0 | K34: =TRUNC(E34+G34+I34, 0) -> 512 | L34: =TRUNC(F34+H34+J34, 0) -> 8340992 | M34: 호표 13 | N34: 44771770C30015F0EAFD95BBD0ECD | Q34: 010102 | R34: T | S34: F | T34: F | AU34: 01010244771770C30015F0EAFD95BBD0ECD | AV34: 2567
A35: 건축물보양 - 석재면, 테라조면 | B35: 하드롱지 | C35: M2 | D35: 2325 | E35: =TRUNC([1]일위대가목록!E17,0) -> 329 | F35: =TRUNC(E35*D35, 0) -> 764925 | G35: =TRUNC([1]일위대가목록!F17,0) -> 936 | H35: =TRUNC(G35*D35, 0) -> 2176200 | I35: =TRUNC([1]일위대가목록!G17,0) -> 0 | J35: =TRUNC(I35*D35, 0) -> 0 | K35: =TRUNC(E35+G35+I35, 0) -> 1265 | L35: =TRUNC(F35+H35+J35, 0) -> 2941125 | M35: 호표 14 | N35: 44771770C30015F0EAC07EB8E4F31 | Q35: 010102 | R35: T | S35: F | T35: F | AU35: 01010244771770C30015F0EAC07EB8E4F31 | AV35: 2568
A36: 건축물보양 - 타일 | B36: 톱밥 | C36: M2 | D36: 4179 | E36: =TRUNC([1]일위대가목록!E18,0) -> 998 | F36: =TRUNC(E36*D36, 0) -> 4170642 | G36: =TRUNC([1]일위대가목록!F18,0) -> 175 | H36: =TRUNC(G36*D36, 0) -> 731325 | I36: =TRUNC([1]일위대가목록!G18,0) -> 0 | J36: =TRUNC(I36*D36, 0) -> 0 | K36: =TRUNC(E36+G36+I36, 0) -> 1173 | L36: =TRUNC(F36+H36+J36, 0) -> 4901967 | M36: 호표 15 | N36: 44771770C30015F0EAC06C3DD7B71 | Q36: 010102 | R36: T | S36: F | T36: F | AU36: 01010244771770C30015F0EAC06C3DD7B71 | AV36: 2569
A45: [ 합 계 ] | F45: =SUM(F26:F44) -> 27701631 | H45: =SUM(H26:H44) -> 556504250 | J45: =SUM(J26:J44) -> 7386680 | L45: =SUM(L26:L44) -> 591592561 | N45: TOTAL
A46: 010103 철근콘크리트공사 | B46: 01.본관동 및 생활관, 후생관 | Q46: 010103
A47: 철근콘크리트용봉강(도급) | B47: 철근콘크리트용봉강, 이형봉강(SD350/400), HD-10, 하치장상차도 | C47: TON | D47: 255.028 | E47: =TRUNC([1]단가대비표!O616,0) -> 0 | F47: =TRUNC(E47*D47, 0) -> 0 | G47: =TRUNC([1]단가대비표!P616,0) -> 0 | H47: =TRUNC(G47*D47, 0) -> 0 | I47: =TRUNC([1]단가대비표!V616,0) -> 0 | J47: =TRUNC(I47*D47, 0) -> 0 | K47: =TRUNC(E47+G47+I47, 0) -> 0 | L47: =TRUNC(F47+H47+J47, 0) -> 0 | N47: 45C61727F3E315DA92B49D6357B297EAC00A9 | Q47: 010103 | R47: F | S47: F | T47: T | AU47: 01010345C61727F3E315DA92B49D6357B297EAC00A9 | AV47: 2046
A48: 철근콘크리트용봉강(도급) | B48: 철근콘크리트용봉강, 이형봉강(SD350/400), HD-13, 하치장상차도 | C48: TON | D48: 128.581 | E48: =TRUNC([1]단가대비표!O617,0) -> 0 | F48: =TRUNC(E48*D48, 0) -> 0 | G48: =TRUNC([1]단가대비표!P617,0) -> 0 | H48: =TRUNC(G48*D48, 0) -> 0 | I48: =TRUNC([1]단가대비표!V617,0) -> 0 | J48: =TRUNC(I48*D48, 0) -> 0 | K48: =TRUNC(E48+G48+I48, 0) -> 0 | L48: =TRUNC(F48+H48+J48, 0) -> 0 | N48: 45C61727F3E315DA92B49D6357B297EAD108F | Q48: 010103 | R48: F | S48: F | T48: T | AU48: 01010345C61727F3E315DA92B49D6357B297EAD108F | AV48: 2047
A49: 철근콘크리트용봉강(도급) | B49: 철근콘크리트용봉강, 이형봉강(SD500), SH-16, 하치장상차도 | C49: TON | D49: 130.995 | E49: =TRUNC([1]단가대비표!O618,0) -> 0 | F49: =TRUNC(E49*D49, 0) -> 0 | G49: =TRUNC([1]단가대비표!P618,0) -> 0 | H49: =TRUNC(G49*D49, 0) -> 0 | I49: =TRUNC([1]단가대비표!V618,0) -> 0 | J49: =TRUNC(I49*D49, 0) -> 0 | K49: =TRUNC(E49+G49+I49, 0) -> 0 | L49: =TRUNC(F49+H49+J49, 0) -> 0 | N49: 45C61727F3E315DA92B49D6357B297EAD108E | Q49: 010103 | R49: F | S49: F | T49: T | AU49: 01010345C61727F3E315DA92B49D6357B297EAD108E | AV49: 2048
A50: 철근콘크리트용봉강(도급) | B50: 철근콘크리트용봉강, 이형봉강(SD500), SH-19, 하치장상차도 | C50: TON | D50: 275.089 | E50: =TRUNC([1]단가대비표!O619,0) -> 0 | F50: =TRUNC(E50*D50, 0) -> 0 | G50: =TRUNC([1]단가대비표!P619,0) -> 0 | H50: =TRUNC(G50*D50, 0) -> 0 | I50: =TRUNC([1]단가대비표!V619,0) -> 0 | J50: =TRUNC(I50*D50, 0) -> 0 | K50: =TRUNC(E50+G50+I50, 0) -> 0 | L50: =TRUNC(F50+H50+J50, 0) -> 0 | N50: 45C61727F3E315DA92B49D6357B297EAD108D | Q50: 010103 | R50: F | S50: F | T50: T | AU50: 01010345C61727F3E315DA92B49D6357B297EAD108D | AV50: 2049
A51: 철근콘크리트용봉강(도급) | B51: 철근콘크리트용봉강, 이형봉강(SD500), SH-22, 하치장상차도 | C51: TON | D51: 459.523 | E51: =TRUNC([1]단가대비표!O620,0) -> 0 | F51: =TRUNC(E51*D51, 0) -> 0 | G51: =TRUNC([1]단가대비표!P620,0) -> 0 | H51: =TRUNC(G51*D51, 0) -> 0 | I51: =TRUNC([1]단가대비표!V620,0) -> 0 | J51: =TRUNC(I51*D51, 0) -> 0 | K51: =TRUNC(E51+G51+I51, 0) -> 0 | L51: =TRUNC(F51+H51+J51, 0) -> 0 | N51: 45C61727F3E315DA92B49D6357B297EAD108C | Q51: 010103 | R51: F | S51: F | T51: T | AU51: 01010345C61727F3E315DA92B49D6357B297EAD108C | AV51: 2050
...
