Workbook

Sheet Sheet1
C1: [공사명] 인천소방학교 이전신축공사 설계용역(기계)
A2: 공종 | B2: 코드 | C2: 품 명 | D2: 규 격 | E2: 단위 | F2: 수량 | G2: 재 료 비 | I2: 노 무 비 | K2: 경 비 | M2: 합 계 | O2: 비고
G3: 단가 | H3: 금액 | I3: 단가 | J3: 금액 | K3: 단가 | L3: 금액 | M3: 단가 | N3: 금액
C4: 010101 장비설치공사
A5: 010101 | B5: MM948385915 | C5: P-102 우수조경펌프(볼류트) | D5: 110LPMx32Mx1.5KW | E5: 대 | F5: 1 | G5: =TRUNC([1]단가대비표!O1356,0) -> 799000 | H5: =TRUNC(F5*G5,0) -> 799000 | I5: 0 | J5: =TRUNC(F5*I5,0) -> 0 | K5: 0 | L5: =TRUNC(F5*K5,0) -> 0 | M5: =G5+I5+K5 -> 799000 | N5: =H5+J5+L5 -> 799000 | T5: 0 | AC5: 1
A6: 010101 | B6: MM938207668 | C6: P-103 냉온수순환펌프(인라인) | D6: 550LPMx30Mx7.5KW | E6: 대 | F6: 2 | G6: =TRUNC([1]단가대비표!O940,0) -> 2103000 | H6: =TRUNC(F6*G6,0) -> 4206000 | I6: 0 | J6: =TRUNC(F6*I6,0) -> 0 | K6: 0 | L6: =TRUNC(F6*K6,0) -> 0 | M6: =G6+I6+K6 -> 2103000 | N6: =H6+J6+L6 -> 4206000 | T6: 0 | AC6: 1
A7: 010101 | B7: MM938207669 | C7: P-104 급탕순환펌프(인라인) | D7: 100LPMx6Mx0.37KW | E7: 대 | F7: 2 | G7: =TRUNC([1]단가대비표!O941,0) -> 1029000 | H7: =TRUNC(F7*G7,0) -> 2058000 | I7: 0 | J7: =TRUNC(F7*I7,0) -> 0 | K7: 0 | L7: =TRUNC(F7*K7,0) -> 0 | M7: =G7+I7+K7 -> 1029000 | N7: =H7+J7+L7 -> 2058000 | T7: 0 | AC7: 1
A8: 010101 | B8: MM938207670 | C8: P-105 배수펌프(수중형) | D8: 480LPMx15Mx2.2KW | E8: 대 | F8: 4 | G8: =TRUNC([1]단가대비표!O942,0) -> 1129000 | H8: =TRUNC(F8*G8,0) -> 4516000 | I8: 0 | J8: =TRUNC(F8*I8,0) -> 0 | K8: 0 | L8: =TRUNC(F8*K8,0) -> 0 | M8: =G8+I8+K8 -> 1129000 | N8: =H8+J8+L8 -> 4516000 | T8: 0 | AC8: 1
A9: 010101 | B9: MM938207671 | C9: P-106 급탕대류펌프(인라인) | D9: 30LPMx1Mx0.03KW | E9: 대 | F9: 2 | G9: =TRUNC([1]단가대비표!O943,0) -> 1029000 | H9: =TRUNC(F9*G9,0) -> 2058000 | I9: 0 | J9: =TRUNC(F9*I9,0) -> 0 | K9: 0 | L9: =TRUNC(F9*K9,0) -> 0 | M9: =G9+I9+K9 -> 1029000 | N9: =H9+J9+L9 -> 2058000 | O9: 수정 | T9: 0 | AC9: 1
A10: 010101 | B10: MM938207673 | C10: FCU-1 팬코일유니트설치비 | D10: 냉방2.09KW 난방3.59KW | E10: 대 | F10: 81 | G10: =TRUNC([1]단가대비표!O945,0) -> 0 | H10: =TRUNC(F10*G10,0) -> 0 | I10: 0 | J10: =TRUNC(F10*I10,0) -> 0 | K10: 0 | L10: =TRUNC(F10*K10,0) -> 0 | M10: =G10+I10+K10 -> 0 | N10: =H10+J10+L10 -> 0 | T10: 0 | AC10: 1
A11: 010101 | B11: MM938207675 | C11: FCU-2 팬코일유니트설치비 | D11: 냉방3.00KW 난방4.77KW | E11: 대 | F11: 5 | G11: =TRUNC([1]단가대비표!O947,0) -> 0 | H11: =TRUNC(F11*G11,0) -> 0 | I11: 0 | J11: =TRUNC(F11*I11,0) -> 0 | K11: 0 | L11: =TRUNC(F11*K11,0) -> 0 | M11: =G11+I11+K11 -> 0 | N11: =H11+J11+L11 -> 0 | T11: 0 | AC11: 1
A12: 010101 | B12: MM938207677 | C12: FCU-4 팬코일유니트설치비 | D12: 냉방3.58KW 난방5.45KW | E12: 대 | F12: 15 | G12: =TRUNC([1]단가대비표!O949,0) -> 0 | H12: =TRUNC(F12*G12,0) -> 0 | I12: 0 | J12: =TRUNC(F12*I12,0) -> 0 | K12: 0 | L12: =TRUNC(F12*K12,0) -> 0 | M12: =G12+I12+K12 -> 0 | N12: =H12+J12+L12 -> 0 | T12: 0 | AC12: 1
A13: 010101 | B13: MM938207679 | C13: FCU-5 팬코일유니트설치비 | D13: 냉방4.77KW 난방7.71KW | E13: 대 | F13: 5 | G13: =TRUNC([1]단가대비표!O951,0) -> 0 | H13: =TRUNC(F13*G13,0) -> 0 | I13: 0 | J13: =TRUNC(F13*I13,0) -> 0 | K13: 0 | L13: =TRUNC(F13*K13,0) -> 0 | M13: =G13+I13+K13 -> 0 | N13: =H13+J13+L13 -> 0 | T13: 0 | AC13: 1
A14: 010101 | B14: MM938207681 | C14: FCU-6 팬코일유니트설치비 | D14: 냉방5.06KW 난방7.09KW | E14: 대 | F14: 5 | G14: =TRUNC([1]단가대비표!O953,0) -> 0 | H14: =TRUNC(F14*G14,0) -> 0 | I14: 0 | J14: =TRUNC(F14*I14,0) -> 0 | K14: 0 | L14: =TRUNC(F14*K14,0) -> 0 | M14: =G14+I14+K14 -> 0 | N14: =H14+J14+L14 -> 0 | T14: 0 | AC14: 1
A15: 010101 | B15: MM938207683 | C15: FCU-7 팬코일유니트설치비 | D15: 냉방6.22KW 난방8.96KW | E15: 대 | F15: 5 | G15: =TRUNC([1]단가대비표!O955,0) -> 0 | H15: =TRUNC(F15*G15,0) -> 0 | I15: 0 | J15: =TRUNC(F15*I15,0) -> 0 | K15: 0 | L15: =TRUNC(F15*K15,0) -> 0 | M15: =G15+I15+K15 -> 0 | N15: =H15+J15+L15 -> 0 | T15: 0 | AC15: 1
A16: 010101 | B16: MM938207685 | C16: FCU-8 팬코일유니트설치비 | D16: 냉방7.39KW 난방10.7KW | E16: 대 | F16: 9 | G16: =TRUNC([1]단가대비표!O957,0) -> 0 | H16: =TRUNC(F16*G16,0) -> 0 | I16: 0 | J16: =TRUNC(F16*I16,0) -> 0 | K16: 0 | L16: =TRUNC(F16*K16,0) -> 0 | M16: =G16+I16+K16 -> 0 | N16: =H16+J16+L16 -> 0 | T16: 0 | AC16: 1
A17: 010101 | B17: MM938207687 | C17: FCU-9 팬코일유니트설치비 | D17: 냉방9.59KW 난방14.19KW | E17: 대 | F17: 10 | G17: =TRUNC([1]단가대비표!O959,0) -> 0 | H17: =TRUNC(F17*G17,0) -> 0 | I17: 0 | J17: =TRUNC(F17*I17,0) -> 0 | K17: 0 | L17: =TRUNC(F17*K17,0) -> 0 | M17: =G17+I17+K17 -> 0 | N17: =H17+J17+L17 -> 0 | T17: 0 | AC17: 1
A18: 010101 | B18: MM938207689 | C18: FCU-10 팬코일유니트설치비 | D18: 냉방11.63KW 난방17.79KW | E18: 대 | F18: 3 | G18: =TRUNC([1]단가대비표!O961,0) -> 0 | H18: =TRUNC(F18*G18,0) -> 0 | I18: 0 | J18: =TRUNC(F18*I18,0) -> 0 | K18: 0 | L18: =TRUNC(F18*K18,0) -> 0 | M18: =G18+I18+K18 -> 0 | N18: =H18+J18+L18 -> 0 | T18: 0 | AC18: 1
A19: 010101 | B19: MM938207691 | C19: FCU-12 팬코일유니트설치비 | D19: 냉방7.33KW 난방12.27KW | E19: 대 | F19: 2 | G19: =TRUNC([1]단가대비표!O963,0) -> 0 | H19: =TRUNC(F19*G19,0) -> 0 | I19: 0 | J19: =TRUNC(F19*I19,0) -> 0 | K19: 0 | L19: =TRUNC(F19*K19,0) -> 0 | M19: =G19+I19+K19 -> 0 | N19: =H19+J19+L19 -> 0 | T19: 0 | AC19: 1
A20: 010101 | B20: MM938207693 | C20: FCU-13 팬코일유니트설치비 | D20: 냉방12.31KW 난방19.77KW | E20: 대 | F20: 1 | G20: =TRUNC([1]단가대비표!O965,0) -> 0 | H20: =TRUNC(F20*G20,0) -> 0 | I20: 0 | J20: =TRUNC(F20*I20,0) -> 0 | K20: 0 | L20: =TRUNC(F20*K20,0) -> 0 | M20: =G20+I20+K20 -> 0 | N20: =H20+J20+L20 -> 0 | T20: 0 | AC20: 1
A21: 010101 | B21: MM938207694 | C21: OF-101 급기휀(인라인)D550 | D21: 8,100CMHx270PAx2.2KW | E21: 대 | F21: 1 | G21: =TRUNC([1]단가대비표!O966,0) -> 1207000 | H21: =TRUNC(F21*G21,0) -> 1207000 | I21: 0 | J21: =TRUNC(F21*I21,0) -> 0 | K21: 0 | L21: =TRUNC(F21*K21,0) -> 0 | M21: =G21+I21+K21 -> 1207000 | N21: =H21+J21+L21 -> 1207000 | T21: 0 | AC21: 1
A22: 010101 | B22: MM938207695 | C22: OF-102 급기휀(인라인)D770 | D22: 13,200CMHx260PAx3.7KW | E22: 대 | F22: 1 | G22: =TRUNC([1]단가대비표!O967,0) -> 1917000 | H22: =TRUNC(F22*G22,0) -> 1917000 | I22: 0 | J22: =TRUNC(F22*I22,0) -> 0 | K22: 0 | L22: =TRUNC(F22*K22,0) -> 0 | M22: =G22+I22+K22 -> 1917000 | N22: =H22+J22+L22 -> 1917000 | T22: 0 | AC22: 1
A23: 010101 | B23: MM938207696 | C23: OF-103 급기휀(인라인)D550 | D23: 7,700CMHx340PAx2.2KW | E23: 대 | F23: 1 | G23: =TRUNC([1]단가대비표!O968,0) -> 1207000 | H23: =TRUNC(F23*G23,0) -> 1207000 | I23: 0 | J23: =TRUNC(F23*I23,0) -> 0 | K23: 0 | L23: =TRUNC(F23*K23,0) -> 0 | M23: =G23+I23+K23 -> 1207000 | N23: =H23+J23+L23 -> 1207000 | T23: 0 | AC23: 1
A24: 010101 | B24: MM938207697 | C24: OF-104 급기휀(시로코)#4.5 | D24: 14,800CMHx270PAx3.7KW | E24: 대 | F24: 1 | G24: =TRUNC([1]단가대비표!O969,0) -> 1431000 | H24: =TRUNC(F24*G24,0) -> 1431000 | I24: 0 | J24: =TRUNC(F24*I24,0) -> 0 | K24: 0 | L24: =TRUNC(F24*K24,0) -> 0 | M24: =G24+I24+K24 -> 1431000 | N24: =H24+J24+L24 -> 1431000 | T24: 0 | AC24: 1
A25: 010101 | B25: MM938207698 | C25: OF-105 급기휀(인라인)D770 | D25: 10,800CMHx240PAx3.7KW | E25: 대 | F25: 1 | G25: =TRUNC([1]단가대비표!O970,0) -> 1917000 | H25: =TRUNC(F25*G25,0) -> 1917000 | I25: 0 | J25: =TRUNC(F25*I25,0) -> 0 | K25: 0 | L25: =TRUNC(F25*K25,0) -> 0 | M25: =G25+I25+K25 -> 1917000 | N25: =H25+J25+L25 -> 1917000 | T25: 0 | AC25: 1
A26: 010101 | B26: MM938207699 | C26: OF-106 급기휀(시로코)#5 | D26: 17,900CMHx240PAx3.7KW | E26: 대 | F26: 1 | G26: =TRUNC([1]단가대비표!O971,0) -> 1559000 | H26: =TRUNC(F26*G26,0) -> 1559000 | I26: 0 | J26: =TRUNC(F26*I26,0) -> 0 | K26: 0 | L26: =TRUNC(F26*K26,0) -> 0 | M26: =G26+I26+K26 -> 1559000 | N26: =H26+J26+L26 -> 1559000 | T26: 0 | AC26: 1
A27: 010101 | B27: MM938207700 | C27: OF-107 급기휀(시로코)#3 | D27: 5,700CMHx190PAx1.5KW | E27: 대 | F27: 1 | G27: =TRUNC([1]단가대비표!O972,0) -> 968000 | H27: =TRUNC(F27*G27,0) -> 968000 | I27: 0 | J27: =TRUNC(F27*I27,0) -> 0 | K27: 0 | L27: =TRUNC(F27*K27,0) -> 0 | M27: =G27+I27+K27 -> 968000 | N27: =H27+J27+L27 -> 968000 | T27: 0 | AC27: 1
A28: 010101 | B28: MM938207701 | C28: OF-108 급기휀(시로코)#2 | D28: 2,500CMHx150PAx0.75KW | E28: 대 | F28: 1 | G28: =TRUNC([1]단가대비표!O973,0) -> 804000 | H28: =TRUNC(F28*G28,0) -> 804000 | I28: 0 | J28: =TRUNC(F28*I28,0) -> 0 | K28: 0 | L28: =TRUNC(F28*K28,0) -> 0 | M28: =G28+I28+K28 -> 804000 | N28: =H28+J28+L28 -> 804000 | T28: 0 | AC28: 1
A29: 010101 | B29: MM938207702 | C29: EF-101 배기휀(인라인)D550 | D29: 8,100CMHx250PAx2.2KW | E29: 대 | F29: 1 | G29: =TRUNC([1]단가대비표!O974,0) -> 1207000 | H29: =TRUNC(F29*G29,0) -> 1207000 | I29: 0 | J29: =TRUNC(F29*I29,0) -> 0 | K29: 0 | L29: =TRUNC(F29*K29,0) -> 0 | M29: =G29+I29+K29 -> 1207000 | N29: =H29+J29+L29 -> 1207000 | T29: 0 | AC29: 1
A30: 010101 | B30: MM938207703 | C30: EF-102 배기휀(인라인)D770 | D30: 13,200CMHx240PAx3.7KW | E30: 대 | F30: 1 | G30: =TRUNC([1]단가대비표!O975,0) -> 1917000 | H30: =TRUNC(F30*G30,0) -> 1917000 | I30: 0 | J30: =TRUNC(F30*I30,0) -> 0 | K30: 0 | L30: =TRUNC(F30*K30,0) -> 0 | M30: =G30+I30+K30 -> 1917000 | N30: =H30+J30+L30 -> 1917000 | T30: 0 | AC30: 1
A31: 010101 | B31: MM938207704 | C31: EF-103 배기휀(인라인)D550 | D31: 7,700CMHx310PAx2.2KW | E31: 대 | F31: 1 | G31: =TRUNC([1]단가대비표!O976,0) -> 1207000 | H31: =TRUNC(F31*G31,0) -> 1207000 | I31: 0 | J31: =TRUNC(F31*I31,0) -> 0 | K31: 0 | L31: =TRUNC(F31*K31,0) -> 0 | M31: =G31+I31+K31 -> 1207000 | N31: =H31+J31+L31 -> 1207000 | T31: 0 | AC31: 1
... A42: 010101 | B42: MM938207715 | C42: EF-114 배기휀(시로코)#2 | D42: 2,500CMHx220PAx0.75KW | E42: 대 | F42: 1 | G42: =TRUNC([1]단가대비표!O987,0) -> 804000 | H42: =TRUNC(F42*G42,0) -> 804000 | I42: 0 | J42: =TRUNC(F42*I42,0) -> 0 | K42: 0 | L42: =TRUNC(F42*K42,0) -> 0 | M42: =G42+I42+K42 -> 804000 | N42: =H42+J42+L42 -> 804000 | T42: 0 | AC42: 1
A43: 010101 | B43: MM938207718 | C43: EF-115 배기휀(시로코)#2 | D43: 1,600CMHx210PAx0.4KW | E43: 대 | F43: 1 | G43: =TRUNC([1]단가대비표!O990,0) -> 804000 | H43: =TRUNC(F43*G43,0) -> 804000 | I43: 0 | J43: =TRUNC(F43*I43,0) -> 0 | K43: 0 | L43: =TRUNC(F43*K43,0) -> 0 | M43: =G43+I43+K43 -> 804000 | N43: =H43+J43+L43 -> 804000 | T43: 0 | AC43: 1
A44: 010101 | B44: MM938207716 | C44: EFU-1 탈취유니트 | D44: 18,500CMH | E44: 대 | F44: 1 | G44: =TRUNC([1]단가대비표!O988,0) -> 40800000 | H44: =TRUNC(F44*G44,0) -> 40800000 | I44: 0 | J44: =TRUNC(F44*I44,0) -> 0 | K44: 0 | L44: =TRUNC(F44*K44,0) -> 0 | M44: =G44+I44+K44 -> 40800000 | N44: =H44+J44+L44 -> 40800000 | T44: 0 | AC44: 1
A45: 010101 | B45: MM938207717 | C45: SFU-1 급기필터 | D45: 14,800CMH | E45: 대 | F45: 1 | G45: =TRUNC([1]단가대비표!O989,0) -> 5000000 | H45: =TRUNC(F45*G45,0) -> 5000000 | I45: 0 | J45: =TRUNC(F45*I45,0) -> 0 | K45: 0 | L45: =TRUNC(F45*K45,0) -> 0 | M45: =G45+I45+K45 -> 5000000 | N45: =H45+J45+L45 -> 5000000 | T45: 0 | AC45: 1
A46: 010101 | B46: MM938207719 | C46: ET-1 팽창탱크(급탕용) | D46: 500LIT(D760*1,544H) | E46: 대 | F46: 1 | G46: =TRUNC([1]단가대비표!O991,0) -> 1700000 | H46: =TRUNC(F46*G46,0) -> 1700000 | I46: 0 | J46: =TRUNC(F46*I46,0) -> 0 | K46: 0 | L46: =TRUNC(F46*K46,0) -> 0 | M46: =G46+I46+K46 -> 1700000 | N46: =H46+J46+L46 -> 1700000 | T46: 0 | AC46: 1
A47: 010101 | B47: MM938207720 | C47: AS-1 팽창기수분리기 | D47: 200LITx1.1KW | E47: 대 | F47: 1 | G47: =TRUNC([1]단가대비표!O992,0) -> 6800000 | H47: =TRUNC(F47*G47,0) -> 6800000 | I47: 0 | J47: =TRUNC(F47*I47,0) -> 0 | K47: 0 | L47: =TRUNC(F47*K47,0) -> 0 | M47: =G47+I47+K47 -> 6800000 | N47: =H47+J47+L47 -> 6800000 | T47: 0 | AC47: 1
A48: 010101 | B48: MM938207730 | C48: 물탱크건식패드 | D48: 350~525mmh | E48: ea | F48: 77 | G48: =TRUNC([1]단가대비표!O1002,0) -> 117000 | H48: =TRUNC(F48*G48,0) -> 9009000 | I48: 0 | J48: =TRUNC(F48*I48,0) -> 0 | K48: 0 | L48: =TRUNC(F48*K48,0) -> 0 | M48: =G48+I48+K48 -> 117000 | N48: =H48+J48+L48 -> 9009000 | T48: 0 | AC48: 1
A49: 010101 | B49: 56900017041 | C49: 노무비 | D49: 보통인부 | E49: 인 | F49: 89 | G49: 0 | H49: =TRUNC(F49*G49,0) -> 0 | I49: =TRUNC([1]단가대비표!O671,0) -> 157068 | J49: =TRUNC(F49*I49,0) -> 13979052 | K49: 0 | L49: =TRUNC(F49*K49,0) -> 0 | M49: =G49+I49+K49 -> 157068 | N49: =H49+J49+L49 -> 13979052 | T49: 0 | W49: 3 | AC49: 1
A50: 010101 | B50: 56900017014 | C50: 노무비 | D50: 기계공 | E50: 인 | F50: 297 | G50: 0 | H50: =TRUNC(F50*G50,0) -> 0 | I50: =TRUNC([1]단가대비표!O664,0) -> 213337 | J50: =TRUNC(F50*I50,0) -> 63361089 | K50: 0 | L50: =TRUNC(F50*K50,0) -> 0 | M50: =G50+I50+K50 -> 213337 | N50: =H50+J50+L50 -> 63361089 | T50: 0 | W50: 3 | AC50: 1
...
