Workbook

Sheet Sheet1
A1: 내역서
A2: 공 종 명 | B2: 규 격 | C2: 수량 | D2: 단위 | E2: 재 료 비 | G2: 노 무 비 | I2: 경 비 | K2: 합 계 | M2: 비 고
E3: 단 가 | F3: 금 액 | G3: 단 가 | H3: 금 액 | I3: 단 가 | J3: 금 액 | K3: 단 가 | L3: 금 액 | S3: 할 증 | T3: 화폐변환 | U3: OP값 | V3: EQ | W3: LA | X3: MA | Y3: 금액계상
A4: ◈ 인천소방학교 이전 신축공사 조경공사(1차+2차 공사) | C4: 1 | D4: 식 | F4: =TRUNC(F5+F6,0) -> 420209764 | H4: =TRUNC(H5+H6,0) -> 534814908 | J4: =TRUNC(J5+J6,0) -> 39547349 | L4: =F4+H4+J4 -> 994572021 | O4: A0001
A5: A. 1차 인천소방학교 이전 신축공사 | C5: 1 | D5: 식 | E5: =F28 -> 369909972 | F5: =TRUNC(E5*C5,0) -> 369909972 | G5: =H28 -> 373623249 | H5: =TRUNC(G5*C5,0) -> 373623249 | I5: =J28 -> 26115986 | J5: =TRUNC(I5*C5,0) -> 26115986 | K5: =E5+G5+I5 -> 769649207 | L5: =F5+H5+J5 -> 769649207 | P5: 10 | R5: A0010 | BI5: =HYPERLINK("#내역서!A7","A0010 →") -> A0010 →
A6: B. 2차 인천소방학교 이전 신축공사 | C6: 1 | D6: 식 | E6: =F52 -> 50299792 | F6: =TRUNC(E6*C6,0) -> 50299792 | G6: =H52 -> 161191659 | H6: =TRUNC(G6*C6,0) -> 161191659 | I6: =J52 -> 13431363 | J6: =TRUNC(I6*C6,0) -> 13431363 | K6: =E6+G6+I6 -> 224922814 | L6: =F6+H6+J6 -> 224922814 | P6: 20 | Q6: S | R6: A0020 | BI6: =HYPERLINK("#내역서!A20","A0020 →") -> A0020 →
A28: A. 1차 인천소방학교 이전 신축공사 | C28: 1 | D28: 식 | F28: =TRUNC(F31+F32+F33+F34+F35+F38,0) -> 369909972 | H28: =TRUNC(H31+H32+H33+H34+H35+H38,0) -> 373623249 | J28: =TRUNC(J31+J32+J33+J34+J35+J38,0) -> 26115986 | L28: =F28+H28+J28 -> 769649207 | O28: A0010
F29: 0 | H29: 0 | J29: 0 | K29: =E29+G29+I29 -> 0 | L29: =F29+H29+J29 -> 0 | P29: 1
A30: . 1]. 도급공사 | D30: 식 | F30: =TRUNC(F31+F32+F33+F34+F35,0) -> 288441785 | H30: =TRUNC(H31+H32+H33+H34+H35,0) -> 373623249 | J30: =TRUNC(J31+J32+J33+J34+J35,0) -> 25675173 | K30: =E30+G30+I30 -> 0 | L30: =F30+H30+J30 -> 687740207 | P30: 5
A31: ..1. 식재공사 | B31: 1차공사 | C31: 1 | D31: 식 | E31: =F76 -> 69442393 | F31: =TRUNC(E31*C31,0) -> 69442393 | G31: =H76 -> 281033530 | H31: =TRUNC(G31*C31,0) -> 281033530 | I31: =J76 -> 20322638 | J31: =TRUNC(I31*C31,0) -> 20322638 | K31: =E31+G31+I31 -> 370798561 | L31: =F31+H31+J31 -> 370798561 | P31: 10 | R31: A0100 | BI31: =HYPERLINK("#내역서!A30","A0100 →") -> A0100 →
A32: ..2. 시설물공사 | B32: 1차공사 | C32: 1 | D32: 식 | E32: =F100 -> 186418324 | F32: =TRUNC(E32*C32,0) -> 186418324 | G32: =H100 -> 32745505 | H32: =TRUNC(G32*C32,0) -> 32745505 | I32: =J100 -> 817702 | J32: =TRUNC(I32*C32,0) -> 817702 | K32: =E32+G32+I32 -> 219981531 | L32: =F32+H32+J32 -> 219981531 | P32: 20 | R32: A0200 | BI32: =HYPERLINK("#내역서!A52","A0200 →") -> A0200 →
A33: ..3. 포장공사 | B33: 1차공사 | C33: 1 | D33: 식 | E33: =F124 -> 28735807 | F33: =TRUNC(E33*C33,0) -> 28735807 | G33: =H124 -> 56824604 | H33: =TRUNC(G33*C33,0) -> 56824604 | I33: =J124 -> 4330039 | J33: =TRUNC(I33*C33,0) -> 4330039 | K33: =E33+G33+I33 -> 89890450 | L33: =F33+H33+J33 -> 89890450 | P33: 30 | R33: A0300 | BI33: =HYPERLINK("#내역서!A69","A0300 →") -> A0300 →
A34: ..4. 부대공사 | B34: 1차공사 | C34: 1 | D34: 식 | E34: =F148 -> 1906944 | F34: =TRUNC(E34*C34,0) -> 1906944 | G34: =H148 -> 1728833 | H34: =TRUNC(G34*C34,0) -> 1728833 | I34: =J148 -> 128639 | J34: =TRUNC(I34*C34,0) -> 128639 | K34: =E34+G34+I34 -> 3764416 | L34: =F34+H34+J34 -> 3764416 | P34: 40 | R34: A0400 | BI34: =HYPERLINK("#내역서!A81","A0400 →") -> A0400 →
A35: ..5. 실내조경 | B35: 1차공사 | C35: 1 | D35: 식 | E35: =F172 -> 1938317 | F35: =TRUNC(E35*C35,0) -> 1938317 | G35: =H172 -> 1290777 | H35: =TRUNC(G35*C35,0) -> 1290777 | I35: =J172 -> 76155 | J35: =TRUNC(I35*C35,0) -> 76155 | K35: =E35+G35+I35 -> 3305249 | L35: =F35+H35+J35 -> 3305249 | P35: 50 | R35: A0500 | BI35: =HYPERLINK("#내역서!A85","A0500 →") -> A0500 →
F36: 0 | H36: 0 | J36: 0 | K36: =E36+G36+I36 -> 0 | L36: =F36+H36+J36 -> 0 | P36: 60
A37: . 2]. 관급 공사 | F37: =TRUNC(F38,0) -> 81468187 | H37: =TRUNC(H38,0) -> 0 | J37: =TRUNC(J38,0) -> 440813 | K37: =E37+G37+I37 -> 0 | L37: =F37+H37+J37 -> 81909000 | P37: 70
A38: ..1. 관급공사 | B38: 도급자/1차공사 | C38: 1 | D38: 식 | E38: =F196 -> 81468187 | F38: =TRUNC(E38*C38,0) -> 81468187 | G38: =H196 -> 0 | H38: =TRUNC(G38*C38,0) -> 0 | I38: =J196 -> 440813 | J38: =TRUNC(I38*C38,0) -> 440813 | K38: =E38+G38+I38 -> 81909000 | L38: =F38+H38+J38 -> 81909000 | P38: 80 | R38: B0100 | BI38: =HYPERLINK("#내역서!A99","B0100 →") -> B0100 →
F39: 0 | H39: 0 | J39: 0 | K39: =E39+G39+I39 -> 0 | L39: =F39+H39+J39 -> 0 | P39: 90
F40: 0 | H40: 0 | J40: 0 | K40: =E40+G40+I40 -> 0 | L40: =F40+H40+J40 -> 0 | P40: 100 | Q40: S
A52: B. 2차 인천소방학교 이전 신축공사 | B52: 조경공사 | C52: 1 | D52: 식 | F52: =TRUNC(F55+F56+F57+F58+F61,0) -> 50299792 | H52: =TRUNC(H55+H56+H57+H58+H61,0) -> 161191659 | J52: =TRUNC(J55+J56+J57+J58+J61,0) -> 13431363 | L52: =F52+H52+J52 -> 224922814 | O52: A0020
F53: 0 | H53: 0 | J53: 0 | K53: =E53+G53+I53 -> 0 | L53: =F53+H53+J53 -> 0 | P53: 1
A54: . 1]. 도급공사 | D54: 식 | F54: =TRUNC(F55+F56+F57+F58,0) -> 39504721 | H54: =TRUNC(H55+H56+H57+H58,0) -> 161191659 | J54: =TRUNC(J55+J56+J57+J58,0) -> 13372434 | K54: =E54+G54+I54 -> 0 | L54: =F54+H54+J54 -> 214068814 | P54: 5
A55: ..1. 식재공사 | B55: 2차공사 | C55: 1 | D55: 식 | E55: =F220 -> 32304436 | F55: =TRUNC(E55*C55,0) -> 32304436 | G55: =H220 -> 150295114 | H55: =TRUNC(G55*C55,0) -> 150295114 | I55: =J220 -> 12560067 | J55: =TRUNC(I55*C55,0) -> 12560067 | K55: =E55+G55+I55 -> 195159617 | L55: =F55+H55+J55 -> 195159617 | P55: 10 | R55: C0100 | BI55: =HYPERLINK("#내역서!A110","C0100 →") -> C0100 →
A56: ..2. 시설물공사 | B56: 2차공사 | C56: 1 | D56: 식 | E56: =F244 -> 649914 | F56: =TRUNC(E56*C56,0) -> 649914 | G56: =H244 -> 3148464 | H56: =TRUNC(G56*C56,0) -> 3148464 | I56: =J244 -> 37660 | J56: =TRUNC(I56*C56,0) -> 37660 | K56: =E56+G56+I56 -> 3836038 | L56: =F56+H56+J56 -> 3836038 | P56: 20 | R56: C0200 | BI56: =HYPERLINK("#내역서!A123","C0200 →") -> C0200 →
A57: ..3. 포장공사 | B57: 2차공사 | C57: 1 | D57: 식 | E57: =F268 -> 6070033 | F57: =TRUNC(E57*C57,0) -> 6070033 | G57: =H268 -> 7448134 | H57: =TRUNC(G57*C57,0) -> 7448134 | I57: =J268 -> 752389 | J57: =TRUNC(I57*C57,0) -> 752389 | K57: =E57+G57+I57 -> 14270556 | L57: =F57+H57+J57 -> 14270556 | P57: 30 | R57: C0300 | BI57: =HYPERLINK("#내역서!A125","C0300 →") -> C0300 →
A58: ..4. 부대공사 | B58: 2차공사 | C58: 1 | D58: 식 | E58: =F292 -> 480338 | F58: =TRUNC(E58*C58,0) -> 480338 | G58: =H292 -> 299947 | H58: =TRUNC(G58*C58,0) -> 299947 | I58: =J292 -> 22318 | J58: =TRUNC(I58*C58,0) -> 22318 | K58: =E58+G58+I58 -> 802603 | L58: =F58+H58+J58 -> 802603 | P58: 40 | R58: C0400 | BI58: =HYPERLINK("#내역서!A129","C0400 →") -> C0400 →
F59: 0 | H59: 0 | J59: 0 | K59: =E59+G59+I59 -> 0 | L59: =F59+H59+J59 -> 0 | P59: 60
A60: . 2]. 관급 공사 | F60: =TRUNC(F61,0) -> 10795071 | H60: =TRUNC(H61,0) -> 0 | J60: =TRUNC(J61,0) -> 58929 | K60: =E60+G60+I60 -> 0 | L60: =F60+H60+J60 -> 10854000 | P60: 70
A61: ..1. 관급공사 | B61: 도급자/2차공사 | C61: 1 | D61: 식 | E61: =F316 -> 10795071 | F61: =TRUNC(E61*C61,0) -> 10795071 | G61: =H316 -> 0 | H61: =TRUNC(G61*C61,0) -> 0 | I61: =J316 -> 58929 | J61: =TRUNC(I61*C61,0) -> 58929 | K61: =E61+G61+I61 -> 10854000 | L61: =F61+H61+J61 -> 10854000 | P61: 80 | Q61: S | R61: D0100 | BI61: =HYPERLINK("#내역서!A132","D0100 →") -> D0100 →
A76: 1. 식재공사 | B76: 1차공사 | C76: 1 | D76: 식 | F76: =TRUNC(F77+F78,0) -> 69442393 | H76: =TRUNC(H77+H78,0) -> 281033530 | J76: =TRUNC(J77+J78,0) -> 20322638 | L76: =F76+H76+J76 -> 370798561 | O76: A0100
A77: 1-1. 식재공사 | B77: 이식공사[정식] | C77: 1 | D77: 식 | E77: =F81 -> 38193569 | F77: =TRUNC(E77*C77,0) -> 38193569 | G77: =H81 -> 245748763 | H77: =TRUNC(G77*C77,0) -> 245748763 | I77: =J81 -> 20322638 | J77: =TRUNC(I77*C77,0) -> 20322638 | K77: =E77+G77+I77 -> 304264970 | L77: =F77+H77+J77 -> 304264970 | P77: 10 | R77: A0110 | BI77: =HYPERLINK("#내역서!A35","A0110 →") -> A0110 →
A78: 1-2. 식재공사 | B78: 신규공사 | C78: 1 | D78: 식 | E78: =F89 -> 31248824 | F78: =TRUNC(E78*C78,0) -> 31248824 | G78: =H89 -> 35284767 | H78: =TRUNC(G78*C78,0) -> 35284767 | I78: =J89 -> 0 | J78: =TRUNC(I78*C78,0) -> 0 | K78: =E78+G78+I78 -> 66533591 | L78: =F78+H78+J78 -> 66533591 | P78: 20 | R78: A0120 | BI78: =HYPERLINK("#내역서!A43","A0120 →") -> A0120 →
F79: 0 | H79: 0 | J79: 0 | K79: =E79+G79+I79 -> 0 | L79: =F79+H79+J79 -> 0 | P79: 30
F80: 0 | H80: 0 | J80: 0 | K80: =E80+G80+I80 -> 0 | L80: =F80+H80+J80 -> 0 | P80: 40
A81: 1-1. 식재공사 | B81: 이식공사[정식] | C81: 1 | D81: 식 | F81: =TRUNC(F82+F83+F84+F85+F86+F87,0) -> 38193569 | H81: =TRUNC(H82+H83+H84+H85+H86+H87,0) -> 245748763 | J81: =TRUNC(J82+J83+J84+J85+J86+J87,0) -> 20322638 | L81: =F81+H81+J81 -> 304264970 | O81: A0110
A82: [이식]소나무 | B82: H10.0xR26 / 정식 | C82: 33 | D82: 주 | E82: ='[1]일위대가목록-호표'!E93 -> 130453 | F82: =TRUNC(E82*C82,0) -> 4304949 | G82: ='[1]일위대가목록-호표'!F93 -> 845531 | H82: =TRUNC(G82*C82,0) -> 27902523 | I82: ='[1]일위대가목록-호표'!G93 -> 69490 | J82: =TRUNC(I82*C82,0) -> 2293170 | K82: =E82+G82+I82 -> 1045474 | L82: =F82+H82+J82 -> 34500642 | M82: No.91 | P82: 10 | R82: TR-ESSM1-01 | T82: T | BI82: =HYPERLINK("#일위대가목록!A96","TR-ESSM1-01 →") -> TR-ESSM1-01 →
A83: [이식]소나무 | B83: H9.0xR21 / 정식(R20기준) | C83: 16 | D83: 주 | E83: ='[1]일위대가목록-호표'!E94 -> 85877 | F83: =TRUNC(E83*C83,0) -> 1374032 | G83: ='[1]일위대가목록-호표'!F94 -> 508359 | H83: =TRUNC(G83*C83,0) -> 8133744 | I83: ='[1]일위대가목록-호표'!G94 -> 43648 | J83: =TRUNC(I83*C83,0) -> 698368 | K83: =E83+G83+I83 -> 637884 | L83: =F83+H83+J83 -> 10206144 | M83: No.92 | P83: 20 | R83: TR-ESSM1-02 | T83: T | BI83: =HYPERLINK("#일위대가목록!A97","TR-ESSM1-02 →") -> TR-ESSM1-02 →
A84: [이식]굴참나무 | B84: H9.0xR28 / 정식 | C84: 35 | D84: 주 | E84: ='[1]일위대가목록-호표'!E95 -> 130713 | F84: =TRUNC(E84*C84,0) -> 4574955 | G84: ='[1]일위대가목록-호표'!F95 -> 845531 | H84: =TRUNC(G84*C84,0) -> 29593585 | I84: ='[1]일위대가목록-호표'!G95 -> 70990 | J84: =TRUNC(I84*C84,0) -> 2484650 | K84: =E84+G84+I84 -> 1047234 | L84: =F84+H84+J84 -> 36653190 | M84: No.93 | P84: 30 | R84: TR-ESSM1-03 | T84: T | BI84: =HYPERLINK("#일위대가목록!A98","TR-ESSM1-03 →") -> TR-ESSM1-03 →
A85: [이식]상수리나무 | B85: H10.0xR26 / 정식 | C85: 197 | D85: 주 | E85: ='[1]일위대가목록-호표'!E96 -> 130453 | F85: =TRUNC(E85*C85,0) -> 25699241 | G85: ='[1]일위대가목록-호표'!F96 -> 845531 | H85: =TRUNC(G85*C85,0) -> 166569607 | I85: ='[1]일위대가목록-호표'!G96 -> 69490 | J85: =TRUNC(I85*C85,0) -> 13689530 | K85: =E85+G85+I85 -> 1045474 | L85: =F85+H85+J85 -> 205958378 | M85: No.94 | P85: 40 | R85: TR-ESSM1-04 | T85: T | BI85: =HYPERLINK("#일위대가목록!A99","TR-ESSM1-04 →") -> TR-ESSM1-04 →
A86: [이식]상수리나무 | B86: H10.0xR20 / 정식 | C86: 20 | D86: 주 | E86: ='[1]일위대가목록-호표'!E97 -> 85877 | F86: =TRUNC(E86*C86,0) -> 1717540 | G86: ='[1]일위대가목록-호표'!F97 -> 508359 | H86: =TRUNC(G86*C86,0) -> 10167180 | I86: ='[1]일위대가목록-호표'!G97 -> 43648 | J86: =TRUNC(I86*C86,0) -> 872960 | K86: =E86+G86+I86 -> 637884 | L86: =F86+H86+J86 -> 12757680 | M86: No.95 | P86: 50 | R86: TR-ESSM1-05 | T86: T | BI86: =HYPERLINK("#일위대가목록!A100","TR-ESSM1-05 →") -> TR-ESSM1-05 →
...
